Workbook
Name ActualEICharge: [2]Hidden_Calculations!$G$3:$G$219
Name ActualRentCharge: [2]Hidden_Calculations!$E$3:$E$219
Name ActualSubsidyCharge: [2]Hidden_Calculations!$F$3:$F$219
Name Concessions: [2]Hidden_Calculations!$K$3:$K$219
Name CurrentSubsidyUnpaidCharges: [2]Hidden_Calculations!$Q$3:$Q$219
Name CurrentUnpaidCharges: [2]Hidden_Calculations!$P$3:$P$219
Name EconomicVacancy: [2]Hidden_Calculations!$D$3:$D$219
Name LossGainToLease: [2]Hidden_Calculations!$B$3:$B$219
Name MarketRent: [2]Hidden_Calculations!$A$3:$A$219
Name NumberOfProperties: '[2]Summarize By - Unit'!$AL$1
Name PotentialRent: [2]Hidden_Calculations!$C$3:$C$219
Name Prepaid: [2]Hidden_Calculations!$R$3:$R$219
Name PropertyCount: '[2]Summarize By - Unit'!$AL$6:$AL$224
Name ReceiptsCurrent: [2]Hidden_Calculations!$N$3:$N$219
Name ReceiptsPrior: [2]Hidden_Calculations!$O$3:$O$219
Name RentAdjustments: [2]Hidden_Calculations!$I$3:$I$219
Name RentalIncome: #REF!
Name SubsidyAdjustments: [2]Hidden_Calculations!$J$3:$J$219
Name TABLE: '[1]Property Profile (Variables)'!$V$1:$Z$21
Name UtilityReimbursement: [2]Hidden_Calculations!$H$3:$H$219
Name Writeoffs: [2]Hidden_Calculations!$L$3:$L$219

Sheet Payroll
R1: -1 | S1: 1 | T1: 2 | U1: 3 | V1: 4 | W1: 5 | X1: 6 | Y1: 7 | Z1: 8 | AA1: 9 | AB1: 10 | AC1: 11 | AD1: 12
AX2: =COUNTA(AZ3:BZ3) -> 27 | AY2: States | CR2: Pay Period | CS2: 1 | CT2: 2 | CU2: 3 | CV2: 4 | CW2: 5 | CX2: 6 | CY2: 7 | CZ2: 8 | DA2: 9 | DB2: 10 | DC2: 11 | DD2: 12 | DE2: 13 | DF2: 14 | DG2: 15 | DH2: 16 | DI2: 17 | DJ2: 18 | DK2: 19 | DL2: 20 | DM2: 21 | DN2: 22 | DO2: 23 | DP2: 24 | DQ2: 25 | DR2: 26 | DS2: 27 | DT2: 28
B3: ← Click this filter and uncheck "Hide" box to hide unused rows. | L3: ='[1]Property Profile (Variables)'!F5 -> The Bluffs | AX3: 45866 | AY3: Date of Rate | AZ3: AK | BA3: AZ | BB3: CA | BC3: CO | BD3: FL | BE3: GA | BF3: ID | BG3: IL | BH3: LA | BI3: MD | BJ3: MN | BK3: MO | BL3: MT | BM3: NC | BN3: NJ | BO3: NM | BP3: NV | BQ3: OH | BR3: OK | BS3: OR | BT3: PA | BU3: SC | BV3: TN | BW3: TX | BX3: UT | BY3: VA | BZ3: WA | CA3: WA Work comp SAFE plus LM Stop Gap rate | CC3: Disability Surcharge -Excludign CA, WA, OR, CO | CH3: ACTIVITY DIRECTOR PAYROLL | CK3: 6980-010 ACTIVITY DIRECTOR PAYROLL | CR3: Month Pay Period begins | CS3: -1 | CT3: =MONTH(CT4) -> 1 | CU3: =MONTH(CU4) -> 1 | CV3: =MONTH(CV4) -> 2 | CW3: =MONTH(CW4) -> 2 | CX3: =MONTH(CX4) -> 3 | CY3: =MONTH(CY4) -> 3 | CZ3: =MONTH(CZ4) -> 3 | DA3: =MONTH(DA4) -> 4 | ... DT3: =MONTH(DT4) -> 1
F4: New Rate | G4: Month of New Rate | L4: ='[1]Property Profile (Variables)'!AA2 -> January 1, 2026 through December 31, 2026 | AW4: =LOOKUP($E$9,$AZ$3:$BZ$3,$AZ4:$BZ4) -> 0.112714 | AX4: Payroll Tax | AY4: 45838 | AZ4: 0.0925 | BA4: 0.1032 | BB4: 0.1215 | BC4: 0.10805 | BD4: 0.084 | BE4: 0.1063 | BF4: 0.0885 | BG4: 0.154 | BH4: 0.0913 | BI4: 0.09 | BJ4: 0.1263 | BK4: 0.09218 | BL4: 0.0945 | BM4: 0.0947 | BN4: 0.1135 | BO4: 0.1362 | BP4: 0.1005 | BQ4: 0.0985 | BR4: 0.1225 | BS4: 0.1005 | BT4: 0.147468 | BU4: 0.0881 | BV4: 0.1095 | BW4: 0.134 | BX4: 0.0965 | BY4: 0.0968 | BZ4: 0.112714 | CC4: eff. | CH4: AREA SUPERVISOR | CK4: 6390-050 AREA SUPERVISOR | CR4: Start Pay Period | CS4: 46012 | CT4: =CS4+14 -> 46026 | CU4: =CT4+14 -> 46040 | CV4: =CU4+14 -> 46054 | CW4: =CV4+14 -> 46068 | CX4: =CW4+14 -> 46082 | CY4: =CX4+14 -> 46096 | CZ4: =CY4+14 -> 46110 | DA4: =CZ4+14 -> 46124 | ... DT4: =DS4+14 -> 46390
C5: Payroll Tax Multiplier | E5: =AW4 -> 0.112714 | H5: Rate updated | J5: =AY4 -> 45838 | S5: Payroll Billings Periods per Month | AW5: =LOOKUP($E$9,$AZ$3:$BZ$3,$AZ5:$BZ5) -> 1.4499 | AX5: Workman's Comp. Non-Office | AY5: 45839 | AZ5: 0.0222 | BA5: 0.0222 | BB5: 0.0574 | BC5: 0.0222 | BD5: 0.0222 | BE5: 0.0222 | BF5: 0.0222 | BG5: 0.0222 | BH5: 0.0222 | BI5: 0.0222 | BJ5: 0.0222 | BK5: 0.0222 | BL5: 0.0222 | BM5: 0.0222 | BN5: 0.0222 | BO5: 0.0222 | BP5: 0.0222 | BQ5: =0.01876+0.0004 -> 0.01916 | BR5: 0.0222 | BS5: 0.0222 | BT5: 0.0222 | BU5: 0.0222 | BV5: 0.0222 | BW5: 0.0222 | BX5: 0.0222 | BY5: 0.0222 | BZ5: 1.4499 | CA5: 0 | CC5: 45505 | CH5: BUS OPERATOR PAYROLL | CK5: 6980-020 BUS OPERATOR PAYROLL | CR5: End Pay Period | CS5: =CS4+13 -> 46025 | CT5: =CT4+13 -> 46039 | CU5: =CU4+13 -> 46053 | CV5: =CV4+13 -> 46067 | CW5: =CW4+13 -> 46081 | CX5: =CX4+13 -> 46095 | CY5: =CY4+13 -> 46109 | CZ5: =CZ4+13 -> 46123 | ... DT5: =DT4+13 -> 46403
C6: Workman's Comp. Multiplier | E6: =AW5 -> 1.4499 | F6: =E6 -> 1.4499 | G6: 7 | H6: Rate updated | J6: =AY5 -> 45839 | S6: ='[1]Property Profile (Variables)'!B23 -> Jan | T6: ='[1]Property Profile (Variables)'!C23 -> Feb | U6: ='[1]Property Profile (Variables)'!D23 -> Mar | V6: ='[1]Property Profile (Variables)'!E23 -> Apr | W6: ='[1]Property Profile (Variables)'!F23 -> May | X6: ='[1]Property Profile (Variables)'!G23 -> Jun | Y6: ='[1]Property Profile (Variables)'!H23 -> Jul | Z6: ='[1]Property Profile (Variables)'!I23 -> Aug | ... AD6: ='[1]Property Profile (Variables)'!M23 -> Dec | AE6: Total | AW6: =LOOKUP($E$9,$AZ$3:$BZ$3,$AZ6:$BZ6) -> 1.4499 | AX6: Workman's Comp. Mult. Office | AY6: =AY5 -> 45839 | AZ6: 0.0222 | BA6: 0.0222 | BB6: 0.0574 | BC6: 0.0222 | BD6: 0.0222 | BE6: 0.0222 | BF6: 0.0222 | BG6: 0.0222 | BH6: 0.0222 | BI6: 0.0222 | BJ6: 0.0222 | BK6: 0.0222 | BL6: 0.0222 | BM6: 0.0222 | BN6: 0.0222 | BO6: 0.0222 | BP6: 0.0222 | BQ6: =BQ5 -> 0.01916 | BR6: 0.0222 | BS6: 0.0222 | BT6: 0.0222 | BU6: 0.0222 | BV6: 0.0222 | BW6: 0.0222 | BX6: 0.0222 | BY6: 0.0222 | BZ6: =BZ5 -> 1.4499 | CA6: 0 | CC6: 0.0077 | CH6: COOK PAYROLL | CK6: 6930-010 COOK PAYROLL | CR6: Pay Day | CS6: =CS5+6 -> 46031 | CT6: =CT5+6 -> 46045 | CU6: =CU5+6 -> 46059 | CV6: =CV5+6 -> 46073 | CW6: =CW5+6 -> 46087 | CX6: =CX5+6 -> 46101 | CY6: =CY5+6 -> 46115 | CZ6: =CZ5+6 -> 46129 | ... DT6: =DT5+6 -> 46409
C7: Monthly Health Benefit Exp per employee: | E7: 1072.15 | S7: 2 | T7: 2 | U7: 2 | V7: 2 | W7: 2 | X7: 2 | Y7: 3 | Z7: 2 | AA7: 2 | AB7: 2 | AC7: 2 | AD7: 3 | AE7: =SUM(S7:AD7) -> 26 | AF7: verified for 2026 | CH7: FOOD SERVICE PAYROLL | CK7: 6930-000 FOOD SERVICE PAYROLL | CR7: Bill Day | CS7: =CS6-2 -> 46029 | CT7: =CT6-2 -> 46043 | CU7: =CU6-2 -> 46057 | CV7: =CV6-2 -> 46071 | CW7: =CW6-2 -> 46085 | CX7: =CX6-2 -> 46099 | CY7: =CY6-2 -> 46113 | CZ7: =CZ6-2 -> 46127 | ... DT7: =DT6-2 -> 46407
R8: Health Benefit Billings | S8: 1 | T8: 2 | U8: 2 | V8: 2 | W8: 2 | X8: 2 | Y8: 2 | Z8: 2 | AA8: 2 | AB8: 2 | AC8: 2 | AD8: 3 | AE8: =SUM(S8:AD8) -> 24 | AF8: verified for 2026 | CH8: MAINT CONSULT SALARY | CK8: 6500-400 MAINT CONSULT SALARY | CR8: Days to accrue | CS8: =MAX(0,CS5-DAY(CS5)+1-CS4)+IF(CS9=1,IF(MONTH(CS4)=MONTH(CS5),14,0),0) -> 11 | CT8: =MAX(0,CT5-DAY(CT5)+1-CT4)+IF(CT9=1,IF(MONTH(CT4)=MONTH(CT5),14,0),0) -> 0 | CU8: =MAX(0,CU5-DAY(CU5)+1-CU4)+IF(CU9=1,IF(MONTH(CU4)=MONTH(CU5),14,0),0) -> 14 | CV8: =MAX(0,CV5-DAY(CV5)+1-CV4)+IF(CV9=1,IF(MONTH(CV4)=MONTH(CV5),14,0),0) -> 0 | CW8: =MAX(0,CW5-DAY(CW5)+1-CW4)+IF(CW9=1,IF(MONTH(CW4)=MONTH(CW5),14,0),0) -> 14 | CX8: =MAX(0,CX5-DAY(CX5)+1-CX4)+IF(CX9=1,IF(MONTH(CX4)=MONTH(CX5),14,0),0) -> 0 | CY8: =MAX(0,CY5-DAY(CY5)+1-CY4)+IF(CY9=1,IF(MONTH(CY4)=MONTH(CY5),14,0),0) -> 14 | CZ8: =MAX(0,CZ5-DAY(CZ5)+1-CZ4)+IF(CZ9=1,IF(MONTH(CZ4)=MONTH(CZ5),14,0),0) -> 3 | ... DT8: =MAX(0,DT5-DAY(DT5)+1-DT4)+IF(DT9=1,IF(MONTH(DT4)=MONTH(DT5),14,0),0) -> 0
C9: State where the property is located | E9: ='[1]Property Profile (Variables)'!F6 -> WA | S9: =IF(S7=3," "&S6,"") | T9: =IF(T7=3," "&T6,"") | U9: =IF(U7=3," "&U6,"") | V9: =IF(V7=3," "&V6,"") | W9: =IF(W7=3," "&W6,"") | X9: =IF(X7=3," "&X6,"") | Y9: =IF(Y7=3," "&Y6,"") -> Jul | Z9: =IF(Z7=3," "&Z6,"") | ... AD9: =IF(AD7=3," "&AD6,"") -> Dec | AE9: =S9&T9&U9&V9&W9&X9&Y9&Z9&AA9&AB9&AC9&AD9 -> Jul Dec | CH9: OTHER MAINTENANCE PAYROLL | CK9: 6500-210 OTHER MAINTENANCE PAYROLL | CS9: =IF(MONTH(CS4)=MONTH(CS7),0,1) -> 1 | CT9: =IF(MONTH(CT4)=MONTH(CT7),0,1) -> 0 | CU9: =IF(MONTH(CU4)=MONTH(CU7),0,1) -> 1 | CV9: =IF(MONTH(CV4)=MONTH(CV7),0,1) -> 0 | CW9: =IF(MONTH(CW4)=MONTH(CW7),0,1) -> 1 | CX9: =IF(MONTH(CX4)=MONTH(CX7),0,1) -> 0 | CY9: =IF(MONTH(CY4)=MONTH(CY7),0,1) -> 1 | CZ9: =IF(MONTH(CZ4)=MONTH(CZ7),0,1) -> 1 | ... DT9: =IF(MONTH(DT4)=MONTH(DT7),0,1) -> 0
C10: PAYROLL ADMIN | E10: 36.66 | G10: Safe Fund Rate | H10: 0.0325 | N10: Does the Property Accrue payroll Monthly? | O10: N | R10: =IF('[1]Property Profile (Variables)'!G26="Y","Delivery Schedule","") | S10: =IF($R10="","",'[1]Rental Revenue'!H77) | T10: =IF($R10="","",'[1]Rental Revenue'!I77) | U10: =IF($R10="","",'[1]Rental Revenue'!J77) | V10: =IF($R10="","",'[1]Rental Revenue'!K77) | W10: =IF($R10="","",'[1]Rental Revenue'!L77) | X10: =IF($R10="","",'[1]Rental Revenue'!M77) | Y10: =IF($R10="","",'[1]Rental Revenue'!N77) | Z10: =IF($R10="","",'[1]Rental Revenue'!O77) | ... AD10: =IF($R10="","",'[1]Rental Revenue'!S77) | CH10: PATROL SERVICE PAYROLL | CK10: 6531-000 PATROL SERVICE PAYROLL | CT10: Jan | CU10: Feb | CV10: Mar | CW10: Apr | CX10: May | CY10: Jun | CZ10: Jul | DA10: Aug | DB10: Sep | DC10: Oct | DD10: Nov | DE10: Dec
G11: 401K Match | H11: 1000 | N11: =IF(O10="Y","","Does the Property Accrue payroll at year end only?") -> Does the Property Accrue payroll at year end only? | O11: N | R11: # Occupied Units | S11: ='[1]Budget Worksheet (Sch A)'!AK6 -> 208.32 | T11: ='[1]Budget Worksheet (Sch A)'!AL6 -> 208.32 | U11: ='[1]Budget Worksheet (Sch A)'!AM6 -> 208.32 | V11: ='[1]Budget Worksheet (Sch A)'!AN6 -> 208.32 | W11: ='[1]Budget Worksheet (Sch A)'!AO6 -> 208.32 | X11: ='[1]Budget Worksheet (Sch A)'!AP6 -> 208.32 | Y11: ='[1]Budget Worksheet (Sch A)'!AQ6 -> 208.32 | Z11: ='[1]Budget Worksheet (Sch A)'!AR6 -> 208.32 | ... AD11: ='[1]Budget Worksheet (Sch A)'!AV6 -> 208.32 | CH11: REPAIRS PAYROLL | CK11: 6540-000 REPAIRS PAYROLL | CT11: 1 | CU11: 0 | CV11: 0 | CW11: 0 | CX11: 0 | CY11: 0 | CZ11: 0 | DA11: 0 | DB11: 0 | DC11: 0 | DD11: 0 | DE11: 0 | DF11: 1
O12: =IF(AND(O11="Y",O10="Y"),"Do Not enter Y in both cells, O9 and O10. If accruing monthly leave N in cell O10.","") | AF12: x | CH12: WAITRESS PAYROLL | CK12: 6930-020 WAITRESS PAYROLL
C13: Position | D13: Name | E13: Monthly Amount of Free Rent | F13: Home Prop. | G13: Health Ins. Head Count | H13: Instructor Lead Trainings | I13: Cell Phone Re-imbursement | J13: Date Hired at the Property | K13: Current Hourly Rate of Pay | L13: Proposed % Increase | M13: Proposed Rate of Pay | N13: Hours/ Week | O13: Overtime Hours/ Week | P13: varia-tion? | Q13: Annual Salary | R13: Weeks per yr of Vacation (Optional) | S13: =S6 -> Jan | T13: =T6 -> Feb | U13: =U6 -> Mar | V13: =V6 -> Apr | W13: =W6 -> May | X13: =X6 -> Jun | Y13: =Y6 -> Jul | Z13: =Z6 -> Aug | ... AE13: =AE6 -> Total | AH13: Footnote Formulas
A14: =IF(F14+G14+H14+M14=0,"Uncheck to Hide","") | B14: 6330-000 MANAGEMENT SALARIES | C14: Community Director 1 | D14: Karen Bryandt | F14: 1 | G14: 1 | I14: 35 | J14: 45678 | K14: 48.07 | L14: 0 | M14: =ROUND(K14*(1+L14),2) -> 48.07 | N14: 40 | P14: =IF(SUM(S15:AD15)>0,1,0) -> 0 | Q14: =M14*N14*52 -> 99985.6 | S14: =IF(S15="",$M14*$N14*2*S$7+$P16*S$7+$O14*$M14*1.5*2*S$7+IF($O$10="Y",(SUMIF($CS$3:$DT$3,S$1,$CS$8:$DT$8)-SUMIF($CS$3:$DT$3,R$1,$CS$8:$DT$8))*($M14*$N14*2*S$7+$P16*S$7+$O14*$M14*1.5*2*S$7)/(S$7*14),0)+IF($O$11="Y",(SUMIF($CS$3:$DT$3,S$1,$CS$8:$DT$8)*CU$11-SUMIF($CS$3:$DT$3,R$1,$CS$8:$DT$8)*CT$11)*($M14*$N14*2*S$7+$P16*S$7+$O14*$M14*1.5*2*S$7)/(S$7*14),0),S15) -> 7691.2 | T14: =IF(T15="",$M14*$N14*2*T$7+$P16*T$7+$O14*$M14*1.5*2*T$7+IF($O$10="Y",(SUMIF($CS$3:$DT$3,T$1,$CS$8:$DT$8)-SUMIF($CS$3:$DT$3,S$1,$CS$8:$DT$8))*($M14*$N14*2*T$7+$P16*T$7+$O14*$M14*1.5*2*T$7)/(T$7*14),0)+IF($O$11="Y",(SUMIF($CS$3:$DT$3,T$1,$CS$8:$DT$8)*CV$11-SUMIF($CS$3:$DT$3,S$1,$CS$8:$DT$8)*CU$11)*($M14*$N14*2*T$7+$P16*T$7+$O14*$M14*1.5*2*T$7)/(T$7*14),0),T15) -> 7691.2 | U14: =IF(U15="",$M14*$N14*2*U$7+$P16*U$7+$O14*$M14*1.5*2*U$7+IF($O$10="Y",(SUMIF($CS$3:$DT$3,U$1,$CS$8:$DT$8)-SUMIF($CS$3:$DT$3,T$1,$CS$8:$DT$8))*($M14*$N14*2*U$7+$P16*U$7+$O14*$M14*1.5*2*U$7)/(U$7*14),0)+IF($O$11="Y",(SUMIF($CS$3:$DT$3,U$1,$CS$8:$DT$8)*CW$11-SUMIF($CS$3:$DT$3,T$1,$CS$8:$DT$8)*CV$11)*($M14*$N14*2*U$7+$P16*U$7+$O14*$M14*1.5*2*U$7)/(U$7*14),0),U15) -> 7691.2 | V14: =IF(V15="",$M14*$N14*2*V$7+$P16*V$7+$O14*$M14*1.5*2*V$7+IF($O$10="Y",(SUMIF($CS$3:$DT$3,V$1,$CS$8:$DT$8)-SUMIF($CS$3:$DT$3,U$1,$CS$8:$DT$8))*($M14*$N14*2*V$7+$P16*V$7+$O14*$M14*1.5*2*V$7)/(V$7*14),0)+IF($O$11="Y",(SUMIF($CS$3:$DT$3,V$1,$CS$8:$DT$8)*CX$11-SUMIF($CS$3:$DT$3,U$1,$CS$8:$DT$8)*CW$11)*($M14*$N14*2*V$7+$P16*V$7+$O14*$M14*1.5*2*V$7)/(V$7*14),0),V15) -> 7691.2 | W14: =IF(W15="",$M14*$N14*2*W$7+$P16*W$7+$O14*$M14*1.5*2*W$7+IF($O$10="Y",(SUMIF($CS$3:$DT$3,W$1,$CS$8:$DT$8)-SUMIF($CS$3:$DT$3,V$1,$CS$8:$DT$8))*($M14*$N14*2*W$7+$P16*W$7+$O14*$M14*1.5*2*W$7)/(W$7*14),0)+IF($O$11="Y",(SUMIF($CS$3:$DT$3,W$1,$CS$8:$DT$8)*CY$11-SUMIF($CS$3:$DT$3,V$1,$CS$8:$DT$8)*CX$11)*($M14*$N14*2*W$7+$P16*W$7+$O14*$M14*1.5*2*W$7)/(W$7*14),0),W15) -> 7691.2 | X14: =IF(X15="",$M14*$N14*2*X$7+$P16*X$7+$O14*$M14*1.5*2*X$7+IF($O$10="Y",(SUMIF($CS$3:$DT$3,X$1,$CS$8:$DT$8)-SUMIF($CS$3:$DT$3,W$1,$CS$8:$DT$8))*($M14*$N14*2*X$7+$P16*X$7+$O14*$M14*1.5*2*X$7)/(X$7*14),0)+IF($O$11="Y",(SUMIF($CS$3:$DT$3,X$1,$CS$8:$DT$8)*CZ$11-SUMIF($CS$3:$DT$3,W$1,$CS$8:$DT$8)*CY$11)*($M14*$N14*2*X$7+$P16*X$7+$O14*$M14*1.5*2*X$7)/(X$7*14),0),X15) -> 7691.2 | Y14: =IF(Y15="",$M14*$N14*2*Y$7+$P16*Y$7+$O14*$M14*1.5*2*Y$7+IF($O$10="Y",(SUMIF($CS$3:$DT$3,Y$1,$CS$8:$DT$8)-SUMIF($CS$3:$DT$3,X$1,$CS$8:$DT$8))*($M14*$N14*2*Y$7+$P16*Y$7+$O14*$M14*1.5*2*Y$7)/(Y$7*14),0)+IF($O$11="Y",(SUMIF($CS$3:$DT$3,Y$1,$CS$8:$DT$8)*DA$11-SUMIF($CS$3:$DT$3,X$1,$CS$8:$DT$8)*CZ$11)*($M14*$N14*2*Y$7+$P16*Y$7+$O14*$M14*1.5*2*Y$7)/(Y$7*14),0),Y15) -> 11536.8 | Z14: =IF(Z15="",$M14*$N14*2*Z$7+$P16*Z$7+$O14*$M14*1.5*2*Z$7+IF($O$10="Y",(SUMIF($CS$3:$DT$3,Z$1,$CS$8:$DT$8)-SUMIF($CS$3:$DT$3,Y$1,$CS$8:$DT$8))*($M14*$N14*2*Z$7+$P16*Z$7+$O14*$M14*1.5*2*Z$7)/(Z$7*14),0)+IF($O$11="Y",(SUMIF($CS$3:$DT$3,Z$1,$CS$8:$DT$8)*DB$11-SUMIF($CS$3:$DT$3,Y$1,$CS$8:$DT$8)*DA$11)*($M14*$N14*2*Z$7+$P16*Z$7+$O14*$M14*1.5*2*Z$7)/(Z$7*14),0),Z15) -> 7691.2 | ... AD14: =IF(AD15="",$M14*$N14*2*AD$7+$P16*AD$7+$O14*$M14*1.5*2*AD$7+IF($O$10="Y",(SUMIF($CS$3:$DT$3,AD$1,$CS$8:$DT$8)-SUMIF($CS$3:$DT$3,AC$1,$CS$8:$DT$8))*($M14*$N14*2*AD$7+$P16*AD$7+$O14*$M14*1.5*2*AD$7)/(AD$7*14),0)+IF($O$11="Y",(SUMIF($CS$3:$DT$3,AD$1,$CS$8:$DT$8)*DF$11-SUMIF($CS$3:$DT$3,AC$1,$CS$8:$DT$8)*DE$11)*($M14*$N14*2*AD$7+$P16*AD$7+$O14*$M14*1.5*2*AD$7)/(AD$7*14),0),AD15) -> 11536.8 | AE14: =SUM(S14:AD14) -> 99985.6
A15: =A14
A16: Do not check this box | P16: =+M14*N14*R14/AE$7 -> 0 | S16: =IF(S15>0,S15-$P16*S$7,+S14-$P16*S$7) -> 7691.2 | T16: =IF(T15>0,T15-$P16*T$7,+T14-$P16*T$7) -> 7691.2 | U16: =IF(U15>0,U15-$P16*U$7,+U14-$P16*U$7) -> 7691.2 | V16: =IF(V15>0,V15-$P16*V$7,+V14-$P16*V$7) -> 7691.2 | W16: =IF(W15>0,W15-$P16*W$7,+W14-$P16*W$7) -> 7691.2 | X16: =IF(X15>0,X15-$P16*X$7,+X14-$P16*X$7) -> 7691.2 | Y16: =IF(Y15>0,Y15-$P16*Y$7,+Y14-$P16*Y$7) -> 11536.8 | Z16: =IF(Z15>0,Z15-$P16*Z$7,+Z14-$P16*Z$7) -> 7691.2 | ... AD16: =IF(AD15>0,AD15-$P16*AD$7,+AD14-$P16*AD$7) -> 11536.8
A17: Do not check this box | S17: =+S16 -> 7691.2 | T17: =+T16+S17 -> 15382.4 | U17: =+U16+T17 -> 23073.6 | V17: =+V16+U17 -> 30764.8 | W17: =+W16+V17 -> 38456 | X17: =+X16+W17 -> 46147.2 | Y17: =+Y16+X17 -> 57684 | Z17: =+Z16+Y17 -> 65375.2 | AA17: =+AA16+Z17 -> 73066.4 | ... AD17: =+AD16+AC17 -> 99985.6
A18: =A15 | C18: Payroll Tax | S18: =IF($E$9="CA",IF(R17<7000,$E$5*S16,($E$5-0.043)*S16),IF($E$9="IL",IF(R17<12960,$E$5*S16,($E$5-0.04125)*S16),IF($E$9="PA",IF(R17<10000,$E$5*S16,($E$5-0.071)*S16),IF($E$9="TX",IF(R17<9000,$E$5*S16,($E$5-0.0363)*S16),IF($E$9="UT",IF(R17<44800,$E$5*S16,0),$E$5*S16))))) -> 866.90592 | T18: =IF($E$9="CA",IF(S17<7000,$E$5*T16,($E$5-0.043)*T16),IF($E$9="IL",IF(S17<12960,$E$5*T16,($E$5-0.04125)*T16),IF($E$9="PA",IF(S17<10000,$E$5*T16,($E$5-0.071)*T16),IF($E$9="TX",IF(S17<9000,$E$5*T16,($E$5-0.0363)*T16),IF($E$9="UT",IF(S17<44800,$E$5*T16,0),$E$5*T16))))) -> 866.90592 | U18: =IF($E$9="CA",IF(T17<7000,$E$5*U16,($E$5-0.043)*U16),IF($E$9="IL",IF(T17<12960,$E$5*U16,($E$5-0.04125)*U16),IF($E$9="PA",IF(T17<10000,$E$5*U16,($E$5-0.071)*U16),IF($E$9="TX",IF(T17<9000,$E$5*U16,($E$5-0.0363)*U16),IF($E$9="UT",IF(T17<44800,$E$5*U16,0),$E$5*U16))))) -> 866.90592 | V18: =IF($E$9="CA",IF(U17<7000,$E$5*V16,($E$5-0.043)*V16),IF($E$9="IL",IF(U17<12960,$E$5*V16,($E$5-0.04125)*V16),IF($E$9="PA",IF(U17<10000,$E$5*V16,($E$5-0.071)*V16),IF($E$9="TX",IF(U17<9000,$E$5*V16,($E$5-0.0363)*V16),IF($E$9="UT",IF(U17<44800,$E$5*V16,0),$E$5*V16))))) -> 866.90592 | W18: =IF($E$9="CA",IF(V17<7000,$E$5*W16,($E$5-0.043)*W16),IF($E$9="IL",IF(V17<12960,$E$5*W16,($E$5-0.04125)*W16),IF($E$9="PA",IF(V17<10000,$E$5*W16,($E$5-0.071)*W16),IF($E$9="TX",IF(V17<9000,$E$5*W16,($E$5-0.0363)*W16),IF($E$9="UT",IF(V17<44800,$E$5*W16,0),$E$5*W16))))) -> 866.90592 | X18: =IF($E$9="CA",IF(W17<7000,$E$5*X16,($E$5-0.043)*X16),IF($E$9="IL",IF(W17<12960,$E$5*X16,($E$5-0.04125)*X16),IF($E$9="PA",IF(W17<10000,$E$5*X16,($E$5-0.071)*X16),IF($E$9="TX",IF(W17<9000,$E$5*X16,($E$5-0.0363)*X16),IF($E$9="UT",IF(W17<44800,$E$5*X16,0),$E$5*X16))))) -> 866.90592 | Y18: =IF($E$9="CA",IF(X17<7000,$E$5*Y16,($E$5-0.043)*Y16),IF($E$9="IL",IF(X17<12960,$E$5*Y16,($E$5-0.04125)*Y16),IF($E$9="PA",IF(X17<10000,$E$5*Y16,($E$5-0.071)*Y16),IF($E$9="TX",IF(X17<9000,$E$5*Y16,($E$5-0.0363)*Y16),IF($E$9="UT",IF(X17<44800,$E$5*Y16,0),$E$5*Y16))))) -> 1300.3589 | Z18: =IF($E$9="CA",IF(Y17<7000,$E$5*Z16,($E$5-0.043)*Z16),IF($E$9="IL",IF(Y17<12960,$E$5*Z16,($E$5-0.04125)*Z16),IF($E$9="PA",IF(Y17<10000,$E$5*Z16,($E$5-0.071)*Z16),IF($E$9="TX",IF(Y17<9000,$E$5*Z16,($E$5-0.0363)*Z16),IF($E$9="UT",IF(Y17<44800,$E$5*Z16,0),$E$5*Z16))))) -> 866.90592 | ... AD18: =IF($E$9="CA",IF(AC17<7000,$E$5*AD16,($E$5-0.043)*AD16),IF($E$9="IL",IF(AC17<12960,$E$5*AD16,($E$5-0.04125)*AD16),IF($E$9="PA",IF(AC17<10000,$E$5*AD16,($E$5-0.071)*AD16),IF($E$9="TX",IF(AC17<9000,$E$5*AD16,($E$5-0.0363)*AD16),IF($E$9="UT",IF(AC17<44800,$E$5*AD16,0),$E$5*AD16))))) -> 1300.3589
A19: =A18 | C19: Workman's Comp | S19: =IF($E$9="WA",IF(S$1<$G$6,$E$6*$N14*2*S$7+$CA$5*S16,$F$6*$N14*2*S$7+$CA$5*S16),IF($E$9="NV",IF(R17>36000,0,IF(S$1<$G$6,$E$6*S16,$F$6*S16)),IF(S$1<$G$6,$E$6*S16,$F$6*S16))) -> 231.984 | T19: =IF($E$9="WA",IF(T$1<$G$6,$E$6*$N14*2*T$7+$CA$5*T16,$F$6*$N14*2*T$7+$CA$5*T16),IF($E$9="NV",IF(S17>36000,0,IF(T$1<$G$6,$E$6*T16,$F$6*T16)),IF(T$1<$G$6,$E$6*T16,$F$6*T16))) -> 231.984 | U19: =IF($E$9="WA",IF(U$1<$G$6,$E$6*$N14*2*U$7+$CA$5*U16,$F$6*$N14*2*U$7+$CA$5*U16),IF($E$9="NV",IF(T17>36000,0,IF(U$1<$G$6,$E$6*U16,$F$6*U16)),IF(U$1<$G$6,$E$6*U16,$F$6*U16))) -> 231.984 | V19: =IF($E$9="WA",IF(V$1<$G$6,$E$6*$N14*2*V$7+$CA$5*V16,$F$6*$N14*2*V$7+$CA$5*V16),IF($E$9="NV",IF(U17>36000,0,IF(V$1<$G$6,$E$6*V16,$F$6*V16)),IF(V$1<$G$6,$E$6*V16,$F$6*V16))) -> 231.984 | W19: =IF($E$9="WA",IF(W$1<$G$6,$E$6*$N14*2*W$7+$CA$5*W16,$F$6*$N14*2*W$7+$CA$5*W16),IF($E$9="NV",IF(V17>36000,0,IF(W$1<$G$6,$E$6*W16,$F$6*W16)),IF(W$1<$G$6,$E$6*W16,$F$6*W16))) -> 231.984 | X19: =IF($E$9="WA",IF(X$1<$G$6,$E$6*$N14*2*X$7+$CA$5*X16,$F$6*$N14*2*X$7+$CA$5*X16),IF($E$9="NV",IF(W17>36000,0,IF(X$1<$G$6,$E$6*X16,$F$6*X16)),IF(X$1<$G$6,$E$6*X16,$F$6*X16))) -> 231.984 | Y19: =IF($E$9="WA",IF(Y$1<$G$6,$E$6*$N14*2*Y$7+$CA$5*Y16,$F$6*$N14*2*Y$7+$CA$5*Y16),IF($E$9="NV",IF(X17>36000,0,IF(Y$1<$G$6,$E$6*Y16,$F$6*Y16)),IF(Y$1<$G$6,$E$6*Y16,$F$6*Y16))) -> 347.976 | Z19: =IF($E$9="WA",IF(Z$1<$G$6,$E$6*$N14*2*Z$7+$CA$5*Z16,$F$6*$N14*2*Z$7+$CA$5*Z16),IF($E$9="NV",IF(Y17>36000,0,IF(Z$1<$G$6,$E$6*Z16,$F$6*Z16)),IF(Z$1<$G$6,$E$6*Z16,$F$6*Z16))) -> 231.984 | ... AD19: =IF($E$9="WA",IF(AD$1<$G$6,$E$6*$N14*2*AD$7+$CA$5*AD16,$F$6*$N14*2*AD$7+$CA$5*AD16),IF($E$9="NV",IF(AC17>36000,0,IF(AD$1<$G$6,$E$6*AD16,$F$6*AD16)),IF(AD$1<$G$6,$E$6*AD16,$F$6*AD16))) -> 347.976
A20: =A19 | C20: 401K Match | S20: =IF(S14=0,0,$H$11/26*S$7*IF(OR($G14=0,$G14=1),1,$G14)) -> 76.923077 | T20: =IF(T14=0,0,$H$11/26*T$7*IF(OR($G14=0,$G14=1),1,$G14)) -> 76.923077 | U20: =IF(U14=0,0,$H$11/26*U$7*IF(OR($G14=0,$G14=1),1,$G14)) -> 76.923077 | V20: =IF(V14=0,0,$H$11/26*V$7*IF(OR($G14=0,$G14=1),1,$G14)) -> 76.923077 | W20: =IF(W14=0,0,$H$11/26*W$7*IF(OR($G14=0,$G14=1),1,$G14)) -> 76.923077 | X20: =IF(X14=0,0,$H$11/26*X$7*IF(OR($G14=0,$G14=1),1,$G14)) -> 76.923077 | Y20: =IF(Y14=0,0,$H$11/26*Y$7*IF(OR($G14=0,$G14=1),1,$G14)) -> 115.38462 | Z20: =IF(Z14=0,0,$H$11/26*Z$7*IF(OR($G14=0,$G14=1),1,$G14)) -> 76.923077 | ... AD20: =IF(AD14=0,0,$H$11/26*AD$7*IF(OR($G14=0,$G14=1),1,$G14)) -> 115.38462
A21: =A19 | C21: =IF($E$9="CA","",$C$269) -> HEALTH INS. & EMPL. BENEFITS | S21: =IF(OR($E$9="CA",$E$9="CO",$E$9="OR",$E$9="WA"),0,IF($G14=0,0,$G14*$E$7*S$8/2+S16*$CC$6)) -> 0 | T21: =IF(OR($E$9="CA",$E$9="CO",$E$9="OR",$E$9="WA"),0,IF($G14=0,0,$G14*$E$7*T$8/2+T16*$CC$6)) -> 0 | U21: =IF(OR($E$9="CA",$E$9="CO",$E$9="OR",$E$9="WA"),0,IF($G14=0,0,$G14*$E$7*U$8/2+U16*$CC$6)) -> 0 | V21: =IF(OR($E$9="CA",$E$9="CO",$E$9="OR",$E$9="WA"),0,IF($G14=0,0,$G14*$E$7*V$8/2+V16*$CC$6)) -> 0 | W21: =IF(OR($E$9="CA",$E$9="CO",$E$9="OR",$E$9="WA"),0,IF($G14=0,0,$G14*$E$7*W$8/2+W16*$CC$6)) -> 0 | X21: =IF(OR($E$9="CA",$E$9="CO",$E$9="OR",$E$9="WA"),0,IF($G14=0,0,$G14*$E$7*X$8/2+X16*$CC$6)) -> 0 | Y21: =IF(OR($E$9="CA",$E$9="CO",$E$9="OR",$E$9="WA"),0,IF($G14=0,0,$G14*$E$7*Y$8/2+Y16*$CC$6)) -> 0 | Z21: =IF(OR($E$9="CA",$E$9="CO",$E$9="OR",$E$9="WA"),0,IF($G14=0,0,$G14*$E$7*Z$8/2+Z16*$CC$6)) -> 0 | ... AD21: =IF(OR($E$9="CA",$E$9="CO",$E$9="OR",$E$9="WA"),0,IF($G14=0,0,$G14*$E$7*AD$8/2+AD16*$CC$6)) -> 0
A22: =IF(F22+G22+H22+M22=0,"Uncheck to Hide","") -> Uncheck to Hide | B22: =B14 -> 6330-000 MANAGEMENT SALARIES | C22: Community Director 2 | I22: 35 | M22: =ROUND(K22*(1+L22),2) -> 0 | P22: =IF(SUM(S23:AD23)>0,1,0) -> 0 | Q22: =M22*N22*52 -> 0 | S22: =IF(S23="",$M22*$N22*2*S$7+$P24*S$7+$O22*$M22*1.5*2*S$7+IF($O$10="Y",(SUMIF($CS$3:$DT$3,S$1,$CS$8:$DT$8)-SUMIF($CS$3:$DT$3,R$1,$CS$8:$DT$8))*($M22*$N22*2*S$7+$P24*S$7+$O22*$M22*1.5*2*S$7)/(S$7*14),0)+IF($O$11="Y",(SUMIF($CS$3:$DT$3,S$1,$CS$8:$DT$8)*CU$11-SUMIF($CS$3:$DT$3,R$1,$CS$8:$DT$8)*CT$11)*($M22*$N22*2*S$7+$P24*S$7+$O22*$M22*1.5*2*S$7)/(S$7*14),0),S23) -> 0 | T22: =IF(T23="",$M22*$N22*2*T$7+$P24*T$7+$O22*$M22*1.5*2*T$7+IF($O$10="Y",(SUMIF($CS$3:$DT$3,T$1,$CS$8:$DT$8)-SUMIF($CS$3:$DT$3,S$1,$CS$8:$DT$8))*($M22*$N22*2*T$7+$P24*T$7+$O22*$M22*1.5*2*T$7)/(T$7*14),0)+IF($O$11="Y",(SUMIF($CS$3:$DT$3,T$1,$CS$8:$DT$8)*CV$11-SUMIF($CS$3:$DT$3,S$1,$CS$8:$DT$8)*CU$11)*($M22*$N22*2*T$7+$P24*T$7+$O22*$M22*1.5*2*T$7)/(T$7*14),0),T23) -> 0 | U22: =IF(U23="",$M22*$N22*2*U$7+$P24*U$7+$O22*$M22*1.5*2*U$7+IF($O$10="Y",(SUMIF($CS$3:$DT$3,U$1,$CS$8:$DT$8)-SUMIF($CS$3:$DT$3,T$1,$CS$8:$DT$8))*($M22*$N22*2*U$7+$P24*U$7+$O22*$M22*1.5*2*U$7)/(U$7*14),0)+IF($O$11="Y",(SUMIF($CS$3:$DT$3,U$1,$CS$8:$DT$8)*CW$11-SUMIF($CS$3:$DT$3,T$1,$CS$8:$DT$8)*CV$11)*($M22*$N22*2*U$7+$P24*U$7+$O22*$M22*1.5*2*U$7)/(U$7*14),0),U23) -> 0 | V22: =IF(V23="",$M22*$N22*2*V$7+$P24*V$7+$O22*$M22*1.5*2*V$7+IF($O$10="Y",(SUMIF($CS$3:$DT$3,V$1,$CS$8:$DT$8)-SUMIF($CS$3:$DT$3,U$1,$CS$8:$DT$8))*($M22*$N22*2*V$7+$P24*V$7+$O22*$M22*1.5*2*V$7)/(V$7*14),0)+IF($O$11="Y",(SUMIF($CS$3:$DT$3,V$1,$CS$8:$DT$8)*CX$11-SUMIF($CS$3:$DT$3,U$1,$CS$8:$DT$8)*CW$11)*($M22*$N22*2*V$7+$P24*V$7+$O22*$M22*1.5*2*V$7)/(V$7*14),0),V23) -> 0 | W22: =IF(W23="",$M22*$N22*2*W$7+$P24*W$7+$O22*$M22*1.5*2*W$7+IF($O$10="Y",(SUMIF($CS$3:$DT$3,W$1,$CS$8:$DT$8)-SUMIF($CS$3:$DT$3,V$1,$CS$8:$DT$8))*($M22*$N22*2*W$7+$P24*W$7+$O22*$M22*1.5*2*W$7)/(W$7*14),0)+IF($O$11="Y",(SUMIF($CS$3:$DT$3,W$1,$CS$8:$DT$8)*CY$11-SUMIF($CS$3:$DT$3,V$1,$CS$8:$DT$8)*CX$11)*($M22*$N22*2*W$7+$P24*W$7+$O22*$M22*1.5*2*W$7)/(W$7*14),0),W23) -> 0 | X22: =IF(X23="",$M22*$N22*2*X$7+$P24*X$7+$O22*$M22*1.5*2*X$7+IF($O$10="Y",(SUMIF($CS$3:$DT$3,X$1,$CS$8:$DT$8)-SUMIF($CS$3:$DT$3,W$1,$CS$8:$DT$8))*($M22*$N22*2*X$7+$P24*X$7+$O22*$M22*1.5*2*X$7)/(X$7*14),0)+IF($O$11="Y",(SUMIF($CS$3:$DT$3,X$1,$CS$8:$DT$8)*CZ$11-SUMIF($CS$3:$DT$3,W$1,$CS$8:$DT$8)*CY$11)*($M22*$N22*2*X$7+$P24*X$7+$O22*$M22*1.5*2*X$7)/(X$7*14),0),X23) -> 0 | Y22: =IF(Y23="",$M22*$N22*2*Y$7+$P24*Y$7+$O22*$M22*1.5*2*Y$7+IF($O$10="Y",(SUMIF($CS$3:$DT$3,Y$1,$CS$8:$DT$8)-SUMIF($CS$3:$DT$3,X$1,$CS$8:$DT$8))*($M22*$N22*2*Y$7+$P24*Y$7+$O22*$M22*1.5*2*Y$7)/(Y$7*14),0)+IF($O$11="Y",(SUMIF($CS$3:$DT$3,Y$1,$CS$8:$DT$8)*DA$11-SUMIF($CS$3:$DT$3,X$1,$CS$8:$DT$8)*CZ$11)*($M22*$N22*2*Y$7+$P24*Y$7+$O22*$M22*1.5*2*Y$7)/(Y$7*14),0),Y23) -> 0 | Z22: =IF(Z23="",$M22*$N22*2*Z$7+$P24*Z$7+$O22*$M22*1.5*2*Z$7+IF($O$10="Y",(SUMIF($CS$3:$DT$3,Z$1,$CS$8:$DT$8)-SUMIF($CS$3:$DT$3,Y$1,$CS$8:$DT$8))*($M22*$N22*2*Z$7+$P24*Z$7+$O22*$M22*1.5*2*Z$7)/(Z$7*14),0)+IF($O$11="Y",(SUMIF($CS$3:$DT$3,Z$1,$CS$8:$DT$8)*DB$11-SUMIF($CS$3:$DT$3,Y$1,$CS$8:$DT$8)*DA$11)*($M22*$N22*2*Z$7+$P24*Z$7+$O22*$M22*1.5*2*Z$7)/(Z$7*14),0),Z23) -> 0 | ... AD22: =IF(AD23="",$M22*$N22*2*AD$7+$P24*AD$7+$O22*$M22*1.5*2*AD$7+IF($O$10="Y",(SUMIF($CS$3:$DT$3,AD$1,$CS$8:$DT$8)-SUMIF($CS$3:$DT$3,AC$1,$CS$8:$DT$8))*($M22*$N22*2*AD$7+$P24*AD$7+$O22*$M22*1.5*2*AD$7)/(AD$7*14),0)+IF($O$11="Y",(SUMIF($CS$3:$DT$3,AD$1,$CS$8:$DT$8)*DF$11-SUMIF($CS$3:$DT$3,AC$1,$CS$8:$DT$8)*DE$11)*($M22*$N22*2*AD$7+$P24*AD$7+$O22*$M22*1.5*2*AD$7)/(AD$7*14),0),AD23) -> 0 | AE22: =SUM(S22:AD22) -> 0
A23: =A22 -> Uncheck to Hide
A24: Do not check this box | P24: =+M22*N22*R22/AE$7 -> 0 | S24: =IF(S23>0,S23-$P24*S$7,+S22-$P24*S$7) -> 0 | T24: =IF(T23>0,T23-$P24*T$7,+T22-$P24*T$7) -> 0 | U24: =IF(U23>0,U23-$P24*U$7,+U22-$P24*U$7) -> 0 | V24: =IF(V23>0,V23-$P24*V$7,+V22-$P24*V$7) -> 0 | W24: =IF(W23>0,W23-$P24*W$7,+W22-$P24*W$7) -> 0 | X24: =IF(X23>0,X23-$P24*X$7,+X22-$P24*X$7) -> 0 | Y24: =IF(Y23>0,Y23-$P24*Y$7,+Y22-$P24*Y$7) -> 0 | Z24: =IF(Z23>0,Z23-$P24*Z$7,+Z22-$P24*Z$7) -> 0 | ... AD24: =IF(AD23>0,AD23-$P24*AD$7,+AD22-$P24*AD$7) -> 0
A25: Do not check this box | S25: =+S24 -> 0 | T25: =+T24+S25 -> 0 | U25: =+U24+T25 -> 0 | V25: =+V24+U25 -> 0 | W25: =+W24+V25 -> 0 | X25: =+X24+W25 -> 0 | Y25: =+Y24+X25 -> 0 | Z25: =+Z24+Y25 -> 0 | AA25: =+AA24+Z25 -> 0 | ... AD25: =+AD24+AC25 -> 0
A26: =A23 -> Uncheck to Hide | C26: Payroll Tax | S26: =IF($E$9="CA",IF(R25<7000,$E$5*S24,($E$5-0.043)*S24),IF($E$9="IL",IF(R25<12960,$E$5*S24,($E$5-0.04125)*S24),IF($E$9="PA",IF(R25<10000,$E$5*S24,($E$5-0.071)*S24),IF($E$9="TX",IF(R25<9000,$E$5*S24,($E$5-0.0363)*S24),$E$5*S24)))) -> 0 | T26: =IF($E$9="CA",IF(S25<7000,$E$5*T24,($E$5-0.043)*T24),IF($E$9="IL",IF(S25<12960,$E$5*T24,($E$5-0.04125)*T24),IF($E$9="PA",IF(S25<10000,$E$5*T24,($E$5-0.071)*T24),IF($E$9="TX",IF(S25<9000,$E$5*T24,($E$5-0.0363)*T24),$E$5*T24)))) -> 0 | U26: =IF($E$9="CA",IF(T25<7000,$E$5*U24,($E$5-0.043)*U24),IF($E$9="IL",IF(T25<12960,$E$5*U24,($E$5-0.04125)*U24),IF($E$9="PA",IF(T25<10000,$E$5*U24,($E$5-0.071)*U24),IF($E$9="TX",IF(T25<9000,$E$5*U24,($E$5-0.0363)*U24),$E$5*U24)))) -> 0 | V26: =IF($E$9="CA",IF(U25<7000,$E$5*V24,($E$5-0.043)*V24),IF($E$9="IL",IF(U25<12960,$E$5*V24,($E$5-0.04125)*V24),IF($E$9="PA",IF(U25<10000,$E$5*V24,($E$5-0.071)*V24),IF($E$9="TX",IF(U25<9000,$E$5*V24,($E$5-0.0363)*V24),$E$5*V24)))) -> 0 | W26: =IF($E$9="CA",IF(V25<7000,$E$5*W24,($E$5-0.043)*W24),IF($E$9="IL",IF(V25<12960,$E$5*W24,($E$5-0.04125)*W24),IF($E$9="PA",IF(V25<10000,$E$5*W24,($E$5-0.071)*W24),IF($E$9="TX",IF(V25<9000,$E$5*W24,($E$5-0.0363)*W24),$E$5*W24)))) -> 0 | X26: =IF($E$9="CA",IF(W25<7000,$E$5*X24,($E$5-0.043)*X24),IF($E$9="IL",IF(W25<12960,$E$5*X24,($E$5-0.04125)*X24),IF($E$9="PA",IF(W25<10000,$E$5*X24,($E$5-0.071)*X24),IF($E$9="TX",IF(W25<9000,$E$5*X24,($E$5-0.0363)*X24),$E$5*X24)))) -> 0 | Y26: =IF($E$9="CA",IF(X25<7000,$E$5*Y24,($E$5-0.043)*Y24),IF($E$9="IL",IF(X25<12960,$E$5*Y24,($E$5-0.04125)*Y24),IF($E$9="PA",IF(X25<10000,$E$5*Y24,($E$5-0.071)*Y24),IF($E$9="TX",IF(X25<9000,$E$5*Y24,($E$5-0.0363)*Y24),$E$5*Y24)))) -> 0 | Z26: =IF($E$9="CA",IF(Y25<7000,$E$5*Z24,($E$5-0.043)*Z24),IF($E$9="IL",IF(Y25<12960,$E$5*Z24,($E$5-0.04125)*Z24),IF($E$9="PA",IF(Y25<10000,$E$5*Z24,($E$5-0.071)*Z24),IF($E$9="TX",IF(Y25<9000,$E$5*Z24,($E$5-0.0363)*Z24),$E$5*Z24)))) -> 0 | ... AD26: =IF($E$9="CA",IF(AC25<7000,$E$5*AD24,($E$5-0.043)*AD24),IF($E$9="IL",IF(AC25<12960,$E$5*AD24,($E$5-0.04125)*AD24),IF($E$9="PA",IF(AC25<10000,$E$5*AD24,($E$5-0.071)*AD24),IF($E$9="TX",IF(AC25<9000,$E$5*AD24,($E$5-0.0363)*AD24),$E$5*AD24)))) -> 0
A27: =A26 -> Uncheck to Hide | C27: Workman's Comp | S27: =IF($E$9="WA",IF(S$1<$G$6,$E$6*$N22*2*S$7+$CA$5*S24,$F$6*$N22*2*S$7+$CA$5*S24),IF($E$9="NV",IF(R25>36000,0,IF(S$1<$G$6,$E$6*S24,$F$6*S24)),IF(S$1<$G$6,$E$6*S24,$F$6*S24))) -> 0 | T27: =IF($E$9="WA",IF(T$1<$G$6,$E$6*$N22*2*T$7+$CA$5*T24,$F$6*$N22*2*T$7+$CA$5*T24),IF($E$9="NV",IF(S25>36000,0,IF(T$1<$G$6,$E$6*T24,$F$6*T24)),IF(T$1<$G$6,$E$6*T24,$F$6*T24))) -> 0 | U27: =IF($E$9="WA",IF(U$1<$G$6,$E$6*$N22*2*U$7+$CA$5*U24,$F$6*$N22*2*U$7+$CA$5*U24),IF($E$9="NV",IF(T25>36000,0,IF(U$1<$G$6,$E$6*U24,$F$6*U24)),IF(U$1<$G$6,$E$6*U24,$F$6*U24))) -> 0 | V27: =IF($E$9="WA",IF(V$1<$G$6,$E$6*$N22*2*V$7+$CA$5*V24,$F$6*$N22*2*V$7+$CA$5*V24),IF($E$9="NV",IF(U25>36000,0,IF(V$1<$G$6,$E$6*V24,$F$6*V24)),IF(V$1<$G$6,$E$6*V24,$F$6*V24))) -> 0 | W27: =IF($E$9="WA",IF(W$1<$G$6,$E$6*$N22*2*W$7+$CA$5*W24,$F$6*$N22*2*W$7+$CA$5*W24),IF($E$9="NV",IF(V25>36000,0,IF(W$1<$G$6,$E$6*W24,$F$6*W24)),IF(W$1<$G$6,$E$6*W24,$F$6*W24))) -> 0 | X27: =IF($E$9="WA",IF(X$1<$G$6,$E$6*$N22*2*X$7+$CA$5*X24,$F$6*$N22*2*X$7+$CA$5*X24),IF($E$9="NV",IF(W25>36000,0,IF(X$1<$G$6,$E$6*X24,$F$6*X24)),IF(X$1<$G$6,$E$6*X24,$F$6*X24))) -> 0 | Y27: =IF($E$9="WA",IF(Y$1<$G$6,$E$6*$N22*2*Y$7+$CA$5*Y24,$F$6*$N22*2*Y$7+$CA$5*Y24),IF($E$9="NV",IF(X25>36000,0,IF(Y$1<$G$6,$E$6*Y24,$F$6*Y24)),IF(Y$1<$G$6,$E$6*Y24,$F$6*Y24))) -> 0 | Z27: =IF($E$9="WA",IF(Z$1<$G$6,$E$6*$N22*2*Z$7+$CA$5*Z24,$F$6*$N22*2*Z$7+$CA$5*Z24),IF($E$9="NV",IF(Y25>36000,0,IF(Z$1<$G$6,$E$6*Z24,$F$6*Z24)),IF(Z$1<$G$6,$E$6*Z24,$F$6*Z24))) -> 0 | ... AD27: =IF($E$9="WA",IF(AD$1<$G$6,$E$6*$N22*2*AD$7+$CA$5*AD24,$F$6*$N22*2*AD$7+$CA$5*AD24),IF($E$9="NV",IF(AC25>36000,0,IF(AD$1<$G$6,$E$6*AD24,$F$6*AD24)),IF(AD$1<$G$6,$E$6*AD24,$F$6*AD24))) -> 0
A28: =A27 -> Uncheck to Hide | C28: 401K Match | S28: =IF(S22=0,0,$H$11/26*S$7*IF(OR($G22=0,$G22=1),1,$G22)) -> 0 | T28: =IF(T22=0,0,$H$11/26*T$7*IF(OR($G22=0,$G22=1),1,$G22)) -> 0 | U28: =IF(U22=0,0,$H$11/26*U$7*IF(OR($G22=0,$G22=1),1,$G22)) -> 0 | V28: =IF(V22=0,0,$H$11/26*V$7*IF(OR($G22=0,$G22=1),1,$G22)) -> 0 | W28: =IF(W22=0,0,$H$11/26*W$7*IF(OR($G22=0,$G22=1),1,$G22)) -> 0 | X28: =IF(X22=0,0,$H$11/26*X$7*IF(OR($G22=0,$G22=1),1,$G22)) -> 0 | Y28: =IF(Y22=0,0,$H$11/26*Y$7*IF(OR($G22=0,$G22=1),1,$G22)) -> 0 | Z28: =IF(Z22=0,0,$H$11/26*Z$7*IF(OR($G22=0,$G22=1),1,$G22)) -> 0 | ... AD28: =IF(AD22=0,0,$H$11/26*AD$7*IF(OR($G22=0,$G22=1),1,$G22)) -> 0
A29: =A27 -> Uncheck to Hide | C29: =IF($E$9="CA","",$C$269) -> HEALTH INS. & EMPL. BENEFITS | S29: =IF(OR($E$9="CA",$E$9="CO",$E$9="OR",$E$9="WA"),0,IF($G22=0,0,$G22*$E$7*S$8/2+S24*$CC$6)) -> 0 | T29: =IF(OR($E$9="CA",$E$9="CO",$E$9="OR",$E$9="WA"),0,IF($G22=0,0,$G22*$E$7*T$8/2+T24*$CC$6)) -> 0 | U29: =IF(OR($E$9="CA",$E$9="CO",$E$9="OR",$E$9="WA"),0,IF($G22=0,0,$G22*$E$7*U$8/2+U24*$CC$6)) -> 0 | V29: =IF(OR($E$9="CA",$E$9="CO",$E$9="OR",$E$9="WA"),0,IF($G22=0,0,$G22*$E$7*V$8/2+V24*$CC$6)) -> 0 | W29: =IF(OR($E$9="CA",$E$9="CO",$E$9="OR",$E$9="WA"),0,IF($G22=0,0,$G22*$E$7*W$8/2+W24*$CC$6)) -> 0 | X29: =IF(OR($E$9="CA",$E$9="CO",$E$9="OR",$E$9="WA"),0,IF($G22=0,0,$G22*$E$7*X$8/2+X24*$CC$6)) -> 0 | Y29: =IF(OR($E$9="CA",$E$9="CO",$E$9="OR",$E$9="WA"),0,IF($G22=0,0,$G22*$E$7*Y$8/2+Y24*$CC$6)) -> 0 | Z29: =IF(OR($E$9="CA",$E$9="CO",$E$9="OR",$E$9="WA"),0,IF($G22=0,0,$G22*$E$7*Z$8/2+Z24*$CC$6)) -> 0 | ... AD29: =IF(OR($E$9="CA",$E$9="CO",$E$9="OR",$E$9="WA"),0,IF($G22=0,0,$G22*$E$7*AD$8/2+AD24*$CC$6)) -> 0
A30: =IF(F30+G30+H30+M30=0,"Uncheck to Hide","") | B30: 6330-100 ASST MANAGER SALARY | C30: Asst Community Director 1 | D30: Michelle Daub | F30: 1 | G30: 1 | I30: 25 | J30: 45490 | K30: 31.25 | L30: 0.03 | M30: =ROUND(K30*(1+L30),2) -> 32.19 | N30: 40 | P30: =IF(SUM(S31:AD31)>0,1,0) -> 0 | Q30: =M30*N30*52 -> 66955.2 | S30: =IF(S31="",$M30*$N30*2*S$7+$P32*S$7+$O30*$M30*1.5*2*S$7+IF($O$10="Y",(SUMIF($CS$3:$DT$3,S$1,$CS$8:$DT$8)-SUMIF($CS$3:$DT$3,R$1,$CS$8:$DT$8))*($M30*$N30*2*S$7+$P32*S$7+$O30*$M30*1.5*2*S$7)/(S$7*14),0)+IF($O$11="Y",(SUMIF($CS$3:$DT$3,S$1,$CS$8:$DT$8)*CU$11-SUMIF($CS$3:$DT$3,R$1,$CS$8:$DT$8)*CT$11)*($M30*$N30*2*S$7+$P32*S$7+$O30*$M30*1.5*2*S$7)/(S$7*14),0),S31) -> 5150.4 | T30: =IF(T31="",$M30*$N30*2*T$7+$P32*T$7+$O30*$M30*1.5*2*T$7+IF($O$10="Y",(SUMIF($CS$3:$DT$3,T$1,$CS$8:$DT$8)-SUMIF($CS$3:$DT$3,S$1,$CS$8:$DT$8))*($M30*$N30*2*T$7+$P32*T$7+$O30*$M30*1.5*2*T$7)/(T$7*14),0)+IF($O$11="Y",(SUMIF($CS$3:$DT$3,T$1,$CS$8:$DT$8)*CV$11-SUMIF($CS$3:$DT$3,S$1,$CS$8:$DT$8)*CU$11)*($M30*$N30*2*T$7+$P32*T$7+$O30*$M30*1.5*2*T$7)/(T$7*14),0),T31) -> 5150.4 | U30: =IF(U31="",$M30*$N30*2*U$7+$P32*U$7+$O30*$M30*1.5*2*U$7+IF($O$10="Y",(SUMIF($CS$3:$DT$3,U$1,$CS$8:$DT$8)-SUMIF($CS$3:$DT$3,T$1,$CS$8:$DT$8))*($M30*$N30*2*U$7+$P32*U$7+$O30*$M30*1.5*2*U$7)/(U$7*14),0)+IF($O$11="Y",(SUMIF($CS$3:$DT$3,U$1,$CS$8:$DT$8)*CW$11-SUMIF($CS$3:$DT$3,T$1,$CS$8:$DT$8)*CV$11)*($M30*$N30*2*U$7+$P32*U$7+$O30*$M30*1.5*2*U$7)/(U$7*14),0),U31) -> 5150.4 | V30: =IF(V31="",$M30*$N30*2*V$7+$P32*V$7+$O30*$M30*1.5*2*V$7+IF($O$10="Y",(SUMIF($CS$3:$DT$3,V$1,$CS$8:$DT$8)-SUMIF($CS$3:$DT$3,U$1,$CS$8:$DT$8))*($M30*$N30*2*V$7+$P32*V$7+$O30*$M30*1.5*2*V$7)/(V$7*14),0)+IF($O$11="Y",(SUMIF($CS$3:$DT$3,V$1,$CS$8:$DT$8)*CX$11-SUMIF($CS$3:$DT$3,U$1,$CS$8:$DT$8)*CW$11)*($M30*$N30*2*V$7+$P32*V$7+$O30*$M30*1.5*2*V$7)/(V$7*14),0),V31) -> 5150.4 | W30: =IF(W31="",$M30*$N30*2*W$7+$P32*W$7+$O30*$M30*1.5*2*W$7+IF($O$10="Y",(SUMIF($CS$3:$DT$3,W$1,$CS$8:$DT$8)-SUMIF($CS$3:$DT$3,V$1,$CS$8:$DT$8))*($M30*$N30*2*W$7+$P32*W$7+$O30*$M30*1.5*2*W$7)/(W$7*14),0)+IF($O$11="Y",(SUMIF($CS$3:$DT$3,W$1,$CS$8:$DT$8)*CY$11-SUMIF($CS$3:$DT$3,V$1,$CS$8:$DT$8)*CX$11)*($M30*$N30*2*W$7+$P32*W$7+$O30*$M30*1.5*2*W$7)/(W$7*14),0),W31) -> 5150.4 | X30: =IF(X31="",$M30*$N30*2*X$7+$P32*X$7+$O30*$M30*1.5*2*X$7+IF($O$10="Y",(SUMIF($CS$3:$DT$3,X$1,$CS$8:$DT$8)-SUMIF($CS$3:$DT$3,W$1,$CS$8:$DT$8))*($M30*$N30*2*X$7+$P32*X$7+$O30*$M30*1.5*2*X$7)/(X$7*14),0)+IF($O$11="Y",(SUMIF($CS$3:$DT$3,X$1,$CS$8:$DT$8)*CZ$11-SUMIF($CS$3:$DT$3,W$1,$CS$8:$DT$8)*CY$11)*($M30*$N30*2*X$7+$P32*X$7+$O30*$M30*1.5*2*X$7)/(X$7*14),0),X31) -> 5150.4 | Y30: =IF(Y31="",$M30*$N30*2*Y$7+$P32*Y$7+$O30*$M30*1.5*2*Y$7+IF($O$10="Y",(SUMIF($CS$3:$DT$3,Y$1,$CS$8:$DT$8)-SUMIF($CS$3:$DT$3,X$1,$CS$8:$DT$8))*($M30*$N30*2*Y$7+$P32*Y$7+$O30*$M30*1.5*2*Y$7)/(Y$7*14),0)+IF($O$11="Y",(SUMIF($CS$3:$DT$3,Y$1,$CS$8:$DT$8)*DA$11-SUMIF($CS$3:$DT$3,X$1,$CS$8:$DT$8)*CZ$11)*($M30*$N30*2*Y$7+$P32*Y$7+$O30*$M30*1.5*2*Y$7)/(Y$7*14),0),Y31) -> 7725.6 | Z30: =IF(Z31="",$M30*$N30*2*Z$7+$P32*Z$7+$O30*$M30*1.5*2*Z$7+IF($O$10="Y",(SUMIF($CS$3:$DT$3,Z$1,$CS$8:$DT$8)-SUMIF($CS$3:$DT$3,Y$1,$CS$8:$DT$8))*($M30*$N30*2*Z$7+$P32*Z$7+$O30*$M30*1.5*2*Z$7)/(Z$7*14),0)+IF($O$11="Y",(SUMIF($CS$3:$DT$3,Z$1,$CS$8:$DT$8)*DB$11-SUMIF($CS$3:$DT$3,Y$1,$CS$8:$DT$8)*DA$11)*($M30*$N30*2*Z$7+$P32*Z$7+$O30*$M30*1.5*2*Z$7)/(Z$7*14),0),Z31) -> 5150.4 | ... AD30: =IF(AD31="",$M30*$N30*2*AD$7+$P32*AD$7+$O30*$M30*1.5*2*AD$7+IF($O$10="Y",(SUMIF($CS$3:$DT$3,AD$1,$CS$8:$DT$8)-SUMIF($CS$3:$DT$3,AC$1,$CS$8:$DT$8))*($M30*$N30*2*AD$7+$P32*AD$7+$O30*$M30*1.5*2*AD$7)/(AD$7*14),0)+IF($O$11="Y",(SUMIF($CS$3:$DT$3,AD$1,$CS$8:$DT$8)*DF$11-SUMIF($CS$3:$DT$3,AC$1,$CS$8:$DT$8)*DE$11)*($M30*$N30*2*AD$7+$P32*AD$7+$O30*$M30*1.5*2*AD$7)/(AD$7*14),0),AD31) -> 7725.6 | AE30: =SUM(S30:AD30) -> 66955.2
A31: =A30
A32: Do not check this box | P32: =+M30*N30*R30/AE$7 -> 0 | S32: =IF(S31>0,S31-$P32*S$7,+S30-$P32*S$7) -> 5150.4 | T32: =IF(T31>0,T31-$P32*T$7,+T30-$P32*T$7) -> 5150.4 | U32: =IF(U31>0,U31-$P32*U$7,+U30-$P32*U$7) -> 5150.4 | V32: =IF(V31>0,V31-$P32*V$7,+V30-$P32*V$7) -> 5150.4 | W32: =IF(W31>0,W31-$P32*W$7,+W30-$P32*W$7) -> 5150.4 | X32: =IF(X31>0,X31-$P32*X$7,+X30-$P32*X$7) -> 5150.4 | Y32: =IF(Y31>0,Y31-$P32*Y$7,+Y30-$P32*Y$7) -> 7725.6 | Z32: =IF(Z31>0,Z31-$P32*Z$7,+Z30-$P32*Z$7) -> 5150.4 | ... AD32: =IF(AD31>0,AD31-$P32*AD$7,+AD30-$P32*AD$7) -> 7725.6
A33: Do not check this box | S33: =+S32 -> 5150.4 | T33: =+T32+S33 -> 10300.8 | U33: =+U32+T33 -> 15451.2 | V33: =+V32+U33 -> 20601.6 | W33: =+W32+V33 -> 25752 | X33: =+X32+W33 -> 30902.4 | Y33: =+Y32+X33 -> 38628 | Z33: =+Z32+Y33 -> 43778.4 | AA33: =+AA32+Z33 -> 48928.8 | ... AD33: =+AD32+AC33 -> 66955.2
A34: =A31 | C34: Payroll Tax | S34: =IF($E$9="CA",IF(R33<7000,$E$5*S32,($E$5-0.043)*S32),IF($E$9="IL",IF(R33<12960,$E$5*S32,($E$5-0.04125)*S32),IF($E$9="PA",IF(R33<10000,$E$5*S32,($E$5-0.071)*S32),IF($E$9="TX",IF(R33<9000,$E$5*S32,($E$5-0.0363)*S32),$E$5*S32)))) -> 580.52219 | T34: =IF($E$9="CA",IF(S33<7000,$E$5*T32,($E$5-0.043)*T32),IF($E$9="IL",IF(S33<12960,$E$5*T32,($E$5-0.04125)*T32),IF($E$9="PA",IF(S33<10000,$E$5*T32,($E$5-0.071)*T32),IF($E$9="TX",IF(S33<9000,$E$5*T32,($E$5-0.0363)*T32),$E$5*T32)))) -> 580.52219 | U34: =IF($E$9="CA",IF(T33<7000,$E$5*U32,($E$5-0.043)*U32),IF($E$9="IL",IF(T33<12960,$E$5*U32,($E$5-0.04125)*U32),IF($E$9="PA",IF(T33<10000,$E$5*U32,($E$5-0.071)*U32),IF($E$9="TX",IF(T33<9000,$E$5*U32,($E$5-0.0363)*U32),$E$5*U32)))) -> 580.52219 | V34: =IF($E$9="CA",IF(U33<7000,$E$5*V32,($E$5-0.043)*V32),IF($E$9="IL",IF(U33<12960,$E$5*V32,($E$5-0.04125)*V32),IF($E$9="PA",IF(U33<10000,$E$5*V32,($E$5-0.071)*V32),IF($E$9="TX",IF(U33<9000,$E$5*V32,($E$5-0.0363)*V32),$E$5*V32)))) -> 580.52219 | W34: =IF($E$9="CA",IF(V33<7000,$E$5*W32,($E$5-0.043)*W32),IF($E$9="IL",IF(V33<12960,$E$5*W32,($E$5-0.04125)*W32),IF($E$9="PA",IF(V33<10000,$E$5*W32,($E$5-0.071)*W32),IF($E$9="TX",IF(V33<9000,$E$5*W32,($E$5-0.0363)*W32),$E$5*W32)))) -> 580.52219 | X34: =IF($E$9="CA",IF(W33<7000,$E$5*X32,($E$5-0.043)*X32),IF($E$9="IL",IF(W33<12960,$E$5*X32,($E$5-0.04125)*X32),IF($E$9="PA",IF(W33<10000,$E$5*X32,($E$5-0.071)*X32),IF($E$9="TX",IF(W33<9000,$E$5*X32,($E$5-0.0363)*X32),$E$5*X32)))) -> 580.52219 | Y34: =IF($E$9="CA",IF(X33<7000,$E$5*Y32,($E$5-0.043)*Y32),IF($E$9="IL",IF(X33<12960,$E$5*Y32,($E$5-0.04125)*Y32),IF($E$9="PA",IF(X33<10000,$E$5*Y32,($E$5-0.071)*Y32),IF($E$9="TX",IF(X33<9000,$E$5*Y32,($E$5-0.0363)*Y32),$E$5*Y32)))) -> 870.78328 | Z34: =IF($E$9="CA",IF(Y33<7000,$E$5*Z32,($E$5-0.043)*Z32),IF($E$9="IL",IF(Y33<12960,$E$5*Z32,($E$5-0.04125)*Z32),IF($E$9="PA",IF(Y33<10000,$E$5*Z32,($E$5-0.071)*Z32),IF($E$9="TX",IF(Y33<9000,$E$5*Z32,($E$5-0.0363)*Z32),$E$5*Z32)))) -> 580.52219 | ... AD34: =IF($E$9="CA",IF(AC33<7000,$E$5*AD32,($E$5-0.043)*AD32),IF($E$9="IL",IF(AC33<12960,$E$5*AD32,($E$5-0.04125)*AD32),IF($E$9="PA",IF(AC33<10000,$E$5*AD32,($E$5-0.071)*AD32),IF($E$9="TX",IF(AC33<9000,$E$5*AD32,($E$5-0.0363)*AD32),$E$5*AD32)))) -> 870.78328
A35: =A34 | C35: Workman's Comp | S35: =IF($E$9="WA",IF(S$1<$G$6,$E$6*$N30*2*S$7+$CA$5*S32,$F$6*$N30*2*S$7+$CA$5*S32),IF($E$9="NV",IF(R33>36000,0,IF(S$1<$G$6,$E$6*S32,$F$6*S32)),IF(S$1<$G$6,$E$6*S32,$F$6*S32))) -> 231.984 | T35: =IF($E$9="WA",IF(T$1<$G$6,$E$6*$N30*2*T$7+$CA$5*T32,$F$6*$N30*2*T$7+$CA$5*T32),IF($E$9="NV",IF(S33>36000,0,IF(T$1<$G$6,$E$6*T32,$F$6*T32)),IF(T$1<$G$6,$E$6*T32,$F$6*T32))) -> 231.984 | U35: =IF($E$9="WA",IF(U$1<$G$6,$E$6*$N30*2*U$7+$CA$5*U32,$F$6*$N30*2*U$7+$CA$5*U32),IF($E$9="NV",IF(T33>36000,0,IF(U$1<$G$6,$E$6*U32,$F$6*U32)),IF(U$1<$G$6,$E$6*U32,$F$6*U32))) -> 231.984 | V35: =IF($E$9="WA",IF(V$1<$G$6,$E$6*$N30*2*V$7+$CA$5*V32,$F$6*$N30*2*V$7+$CA$5*V32),IF($E$9="NV",IF(U33>36000,0,IF(V$1<$G$6,$E$6*V32,$F$6*V32)),IF(V$1<$G$6,$E$6*V32,$F$6*V32))) -> 231.984 | W35: =IF($E$9="WA",IF(W$1<$G$6,$E$6*$N30*2*W$7+$CA$5*W32,$F$6*$N30*2*W$7+$CA$5*W32),IF($E$9="NV",IF(V33>36000,0,IF(W$1<$G$6,$E$6*W32,$F$6*W32)),IF(W$1<$G$6,$E$6*W32,$F$6*W32))) -> 231.984 | X35: =IF($E$9="WA",IF(X$1<$G$6,$E$6*$N30*2*X$7+$CA$5*X32,$F$6*$N30*2*X$7+$CA$5*X32),IF($E$9="NV",IF(W33>36000,0,IF(X$1<$G$6,$E$6*X32,$F$6*X32)),IF(X$1<$G$6,$E$6*X32,$F$6*X32))) -> 231.984 | Y35: =IF($E$9="WA",IF(Y$1<$G$6,$E$6*$N30*2*Y$7+$CA$5*Y32,$F$6*$N30*2*Y$7+$CA$5*Y32),IF($E$9="NV",IF(X33>36000,0,IF(Y$1<$G$6,$E$6*Y32,$F$6*Y32)),IF(Y$1<$G$6,$E$6*Y32,$F$6*Y32))) -> 347.976 | Z35: =IF($E$9="WA",IF(Z$1<$G$6,$E$6*$N30*2*Z$7+$CA$5*Z32,$F$6*$N30*2*Z$7+$CA$5*Z32),IF($E$9="NV",IF(Y33>36000,0,IF(Z$1<$G$6,$E$6*Z32,$F$6*Z32)),IF(Z$1<$G$6,$E$6*Z32,$F$6*Z32))) -> 231.984 | ... AD35: =IF($E$9="WA",IF(AD$1<$G$6,$E$6*$N30*2*AD$7+$CA$5*AD32,$F$6*$N30*2*AD$7+$CA$5*AD32),IF($E$9="NV",IF(AC33>36000,0,IF(AD$1<$G$6,$E$6*AD32,$F$6*AD32)),IF(AD$1<$G$6,$E$6*AD32,$F$6*AD32))) -> 347.976
A36: =A35 | C36: 401K Match | S36: =IF(S30=0,0,$H$11/26*S$7*IF(OR($G30=0,$G30=1),1,$G30)) -> 76.923077 | T36: =IF(T30=0,0,$H$11/26*T$7*IF(OR($G30=0,$G30=1),1,$G30)) -> 76.923077 | U36: =IF(U30=0,0,$H$11/26*U$7*IF(OR($G30=0,$G30=1),1,$G30)) -> 76.923077 | V36: =IF(V30=0,0,$H$11/26*V$7*IF(OR($G30=0,$G30=1),1,$G30)) -> 76.923077 | W36: =IF(W30=0,0,$H$11/26*W$7*IF(OR($G30=0,$G30=1),1,$G30)) -> 76.923077 | X36: =IF(X30=0,0,$H$11/26*X$7*IF(OR($G30=0,$G30=1),1,$G30)) -> 76.923077 | Y36: =IF(Y30=0,0,$H$11/26*Y$7*IF(OR($G30=0,$G30=1),1,$G30)) -> 115.38462 | Z36: =IF(Z30=0,0,$H$11/26*Z$7*IF(OR($G30=0,$G30=1),1,$G30)) -> 76.923077 | ... AD36: =IF(AD30=0,0,$H$11/26*AD$7*IF(OR($G30=0,$G30=1),1,$G30)) -> 115.38462
A37: =A35 | C37: =IF($E$9="CA","",$C$269) -> HEALTH INS. & EMPL. BENEFITS | S37: =IF(OR($E$9="CA",$E$9="CO",$E$9="OR",$E$9="WA"),0,IF($G30=0,0,$G30*$E$7*S$8/2+S32*$CC$6)) -> 0 | T37: =IF(OR($E$9="CA",$E$9="CO",$E$9="OR",$E$9="WA"),0,IF($G30=0,0,$G30*$E$7*T$8/2+T32*$CC$6)) -> 0 | U37: =IF(OR($E$9="CA",$E$9="CO",$E$9="OR",$E$9="WA"),0,IF($G30=0,0,$G30*$E$7*U$8/2+U32*$CC$6)) -> 0 | V37: =IF(OR($E$9="CA",$E$9="CO",$E$9="OR",$E$9="WA"),0,IF($G30=0,0,$G30*$E$7*V$8/2+V32*$CC$6)) -> 0 | W37: =IF(OR($E$9="CA",$E$9="CO",$E$9="OR",$E$9="WA"),0,IF($G30=0,0,$G30*$E$7*W$8/2+W32*$CC$6)) -> 0 | X37: =IF(OR($E$9="CA",$E$9="CO",$E$9="OR",$E$9="WA"),0,IF($G30=0,0,$G30*$E$7*X$8/2+X32*$CC$6)) -> 0 | Y37: =IF(OR($E$9="CA",$E$9="CO",$E$9="OR",$E$9="WA"),0,IF($G30=0,0,$G30*$E$7*Y$8/2+Y32*$CC$6)) -> 0 | Z37: =IF(OR($E$9="CA",$E$9="CO",$E$9="OR",$E$9="WA"),0,IF($G30=0,0,$G30*$E$7*Z$8/2+Z32*$CC$6)) -> 0 | ... AD37: =IF(OR($E$9="CA",$E$9="CO",$E$9="OR",$E$9="WA"),0,IF($G30=0,0,$G30*$E$7*AD$8/2+AD32*$CC$6)) -> 0
A38: =IF(F38+G38+H38+M38=0,"Uncheck to Hide","") -> Uncheck to Hide | B38: =B30 -> 6330-100 ASST MANAGER SALARY | C38: Asst Community Director 2 | I38: 25 | M38: =ROUND(K38*(1+L38),2) -> 0 | P38: =IF(SUM(S39:AD39)>0,1,0) -> 0 | Q38: =M38*N38*52 -> 0 | S38: =IF(S39="",$M38*$N38*2*S$7+$P40*S$7+$O38*$M38*1.5*2*S$7+IF($O$10="Y",(SUMIF($CS$3:$DT$3,S$1,$CS$8:$DT$8)-SUMIF($CS$3:$DT$3,R$1,$CS$8:$DT$8))*($M38*$N38*2*S$7+$P40*S$7+$O38*$M38*1.5*2*S$7)/(S$7*14),0)+IF($O$11="Y",(SUMIF($CS$3:$DT$3,S$1,$CS$8:$DT$8)*CU$11-SUMIF($CS$3:$DT$3,R$1,$CS$8:$DT$8)*CT$11)*($M38*$N38*2*S$7+$P40*S$7+$O38*$M38*1.5*2*S$7)/(S$7*14),0),S39) -> 0 | T38: =IF(T39="",$M38*$N38*2*T$7+$P40*T$7+$O38*$M38*1.5*2*T$7+IF($O$10="Y",(SUMIF($CS$3:$DT$3,T$1,$CS$8:$DT$8)-SUMIF($CS$3:$DT$3,S$1,$CS$8:$DT$8))*($M38*$N38*2*T$7+$P40*T$7+$O38*$M38*1.5*2*T$7)/(T$7*14),0)+IF($O$11="Y",(SUMIF($CS$3:$DT$3,T$1,$CS$8:$DT$8)*CV$11-SUMIF($CS$3:$DT$3,S$1,$CS$8:$DT$8)*CU$11)*($M38*$N38*2*T$7+$P40*T$7+$O38*$M38*1.5*2*T$7)/(T$7*14),0),T39) -> 0 | U38: =IF(U39="",$M38*$N38*2*U$7+$P40*U$7+$O38*$M38*1.5*2*U$7+IF($O$10="Y",(SUMIF($CS$3:$DT$3,U$1,$CS$8:$DT$8)-SUMIF($CS$3:$DT$3,T$1,$CS$8:$DT$8))*($M38*$N38*2*U$7+$P40*U$7+$O38*$M38*1.5*2*U$7)/(U$7*14),0)+IF($O$11="Y",(SUMIF($CS$3:$DT$3,U$1,$CS$8:$DT$8)*CW$11-SUMIF($CS$3:$DT$3,T$1,$CS$8:$DT$8)*CV$11)*($M38*$N38*2*U$7+$P40*U$7+$O38*$M38*1.5*2*U$7)/(U$7*14),0),U39) -> 0 | V38: =IF(V39="",$M38*$N38*2*V$7+$P40*V$7+$O38*$M38*1.5*2*V$7+IF($O$10="Y",(SUMIF($CS$3:$DT$3,V$1,$CS$8:$DT$8)-SUMIF($CS$3:$DT$3,U$1,$CS$8:$DT$8))*($M38*$N38*2*V$7+$P40*V$7+$O38*$M38*1.5*2*V$7)/(V$7*14),0)+IF($O$11="Y",(SUMIF($CS$3:$DT$3,V$1,$CS$8:$DT$8)*CX$11-SUMIF($CS$3:$DT$3,U$1,$CS$8:$DT$8)*CW$11)*($M38*$N38*2*V$7+$P40*V$7+$O38*$M38*1.5*2*V$7)/(V$7*14),0),V39) -> 0 | W38: =IF(W39="",$M38*$N38*2*W$7+$P40*W$7+$O38*$M38*1.5*2*W$7+IF($O$10="Y",(SUMIF($CS$3:$DT$3,W$1,$CS$8:$DT$8)-SUMIF($CS$3:$DT$3,V$1,$CS$8:$DT$8))*($M38*$N38*2*W$7+$P40*W$7+$O38*$M38*1.5*2*W$7)/(W$7*14),0)+IF($O$11="Y",(SUMIF($CS$3:$DT$3,W$1,$CS$8:$DT$8)*CY$11-SUMIF($CS$3:$DT$3,V$1,$CS$8:$DT$8)*CX$11)*($M38*$N38*2*W$7+$P40*W$7+$O38*$M38*1.5*2*W$7)/(W$7*14),0),W39) -> 0 | X38: =IF(X39="",$M38*$N38*2*X$7+$P40*X$7+$O38*$M38*1.5*2*X$7+IF($O$10="Y",(SUMIF($CS$3:$DT$3,X$1,$CS$8:$DT$8)-SUMIF($CS$3:$DT$3,W$1,$CS$8:$DT$8))*($M38*$N38*2*X$7+$P40*X$7+$O38*$M38*1.5*2*X$7)/(X$7*14),0)+IF($O$11="Y",(SUMIF($CS$3:$DT$3,X$1,$CS$8:$DT$8)*CZ$11-SUMIF($CS$3:$DT$3,W$1,$CS$8:$DT$8)*CY$11)*($M38*$N38*2*X$7+$P40*X$7+$O38*$M38*1.5*2*X$7)/(X$7*14),0),X39) -> 0 | Y38: =IF(Y39="",$M38*$N38*2*Y$7+$P40*Y$7+$O38*$M38*1.5*2*Y$7+IF($O$10="Y",(SUMIF($CS$3:$DT$3,Y$1,$CS$8:$DT$8)-SUMIF($CS$3:$DT$3,X$1,$CS$8:$DT$8))*($M38*$N38*2*Y$7+$P40*Y$7+$O38*$M38*1.5*2*Y$7)/(Y$7*14),0)+IF($O$11="Y",(SUMIF($CS$3:$DT$3,Y$1,$CS$8:$DT$8)*DA$11-SUMIF($CS$3:$DT$3,X$1,$CS$8:$DT$8)*CZ$11)*($M38*$N38*2*Y$7+$P40*Y$7+$O38*$M38*1.5*2*Y$7)/(Y$7*14),0),Y39) -> 0 | Z38: =IF(Z39="",$M38*$N38*2*Z$7+$P40*Z$7+$O38*$M38*1.5*2*Z$7+IF($O$10="Y",(SUMIF($CS$3:$DT$3,Z$1,$CS$8:$DT$8)-SUMIF($CS$3:$DT$3,Y$1,$CS$8:$DT$8))*($M38*$N38*2*Z$7+$P40*Z$7+$O38*$M38*1.5*2*Z$7)/(Z$7*14),0)+IF($O$11="Y",(SUMIF($CS$3:$DT$3,Z$1,$CS$8:$DT$8)*DB$11-SUMIF($CS$3:$DT$3,Y$1,$CS$8:$DT$8)*DA$11)*($M38*$N38*2*Z$7+$P40*Z$7+$O38*$M38*1.5*2*Z$7)/(Z$7*14),0),Z39) -> 0 | ... AD38: =IF(AD39="",$M38*$N38*2*AD$7+$P40*AD$7+$O38*$M38*1.5*2*AD$7+IF($O$10="Y",(SUMIF($CS$3:$DT$3,AD$1,$CS$8:$DT$8)-SUMIF($CS$3:$DT$3,AC$1,$CS$8:$DT$8))*($M38*$N38*2*AD$7+$P40*AD$7+$O38*$M38*1.5*2*AD$7)/(AD$7*14),0)+IF($O$11="Y",(SUMIF($CS$3:$DT$3,AD$1,$CS$8:$DT$8)*DF$11-SUMIF($CS$3:$DT$3,AC$1,$CS$8:$DT$8)*DE$11)*($M38*$N38*2*AD$7+$P40*AD$7+$O38*$M38*1.5*2*AD$7)/(AD$7*14),0),AD39) -> 0 | AE38: =SUM(S38:AD38) -> 0
A39: =A38 -> Uncheck to Hide
A40: Do not check this box | P40: =+M38*N38*R38/AE$7 -> 0 | S40: =IF(S39>0,S39-$P40*S$7,+S38-$P40*S$7) -> 0 | T40: =IF(T39>0,T39-$P40*T$7,+T38-$P40*T$7) -> 0 | U40: =IF(U39>0,U39-$P40*U$7,+U38-$P40*U$7) -> 0 | V40: =IF(V39>0,V39-$P40*V$7,+V38-$P40*V$7) -> 0 | W40: =IF(W39>0,W39-$P40*W$7,+W38-$P40*W$7) -> 0 | X40: =IF(X39>0,X39-$P40*X$7,+X38-$P40*X$7) -> 0 | Y40: =IF(Y39>0,Y39-$P40*Y$7,+Y38-$P40*Y$7) -> 0 | Z40: =IF(Z39>0,Z39-$P40*Z$7,+Z38-$P40*Z$7) -> 0 | ... AD40: =IF(AD39>0,AD39-$P40*AD$7,+AD38-$P40*AD$7) -> 0
...
